export class AppError extends Error {
  public statusCode: number;
  public isOperational: boolean;

  constructor(message: string, statusCode: number = 500, isOperational: boolean = true) {
    super(message);
    this.statusCode = statusCode;
    this.isOperational = isOperational;

    Error.captureStackTrace(this, this.constructor);
  }
}

export class ValidationError extends AppError {
  constructor(message: string) {
    super(message, 400);
  }
}

export class AuthenticationError extends AppError {
  constructor(message: string = 'Authentication failed') {
    super(message, 401);
  }
}

export class AuthorizationError extends AppError {
  constructor(message: string = 'Insufficient permissions') {
    super(message, 403);
  }
}

export class NotFoundError extends AppError {
  constructor(message: string = 'Resource not found') {
    super(message, 404);
  }
}

export class ConflictError extends AppError {
  constructor(message: string = 'Resource already exists') {
    super(message, 409);
  }
}

// Global error handler
export const errorHandler = (error: Error, req: any, res: any, next: any): void => {
  console.error('Error:', error);

  if (error instanceof AppError) {
    res.status(error.statusCode).json({
      success: false,
      message: error.message,
    });
    return;
  }

  // Log unexpected errors
  console.error('Unexpected error:', error);

  res.status(500).json({
    success: false,
    message: 'Internal server error',
  });
};

// Async error wrapper
export const asyncHandler = (fn: Function) => {
  return (req: any, res: any, next: any) => {
    Promise.resolve(fn(req, res, next)).catch(next);
  };
};